Workbook
Name NativeTimeline_Date: #N/A
Name rdAmt: 'Raw Data'!$N$2:$N$251
Name rdCat: 'Raw Data'!$G$2:$G$251
Name rdCust: 'Raw Data'!$D$2:$D$251
Name rdCustID: 'Raw Data'!$C$2:$C$251
Name rdDate: 'Raw Data'!$B$2:$B$251
Name rdID: 'Raw Data'!$A$2:$A$251
Name rdPay: 'Raw Data'!$J$2:$J$251
Name rdPrice: 'Raw Data'!$I$2:$I$251
Name rdProd: 'Raw Data'!$F$2:$F$251
Name rdProdID: 'Raw Data'!$E$2:$E$251
Name rdQty: 'Raw Data'!$H$2:$H$251
Name rdReg: 'Raw Data'!$K$2:$K$251
Name rdSeg: 'Raw Data'!$L$2:$L$251
Name rdSince: 'Raw Data'!$M$2:$M$251
Name rdX: 'Raw Data'!$H$2:$I$251
Name Slicer_Category: #N/A
Name Slicer_Category1: #N/A
Name Slicer_Category2: #N/A
Name Slicer_Region: #N/A
Name Slicer_Region1: #N/A
Name Slicer_Region2: #N/A

Sheet Instructions
A1: PR. Final Project - "Data Intelligence Dashboard"
A2: Dataset: Use the 'Final Project Dataset' sheet containing 200+ records of customer transactions. Objective: Create a full-fledged analysis and reporting solution using Excel to analyze customer transactions, find insights, and build visualizations and dashboards. Key Topics to Implement: - Date & Time Functions: TODAY, NOW, DATEDIF, EOMONTH - FILTER Function for multi-value returns - Conditional Formatting with Icons/Arrows - Create Timestamp (using NOW and iterative calculations) - WHAT-IF Analysis: Scenario Manager, Goal Seek - Linear Regression using Data Analysis Toolpak - Data Analysis & Storytelling from the dataset - Use GroupBy concepts to find High-Value Customers using formulas - Create Dashboard using: - Pivot Tables - Pivot Charts (Bar, Line, Pie) - Slicers and Timelines - KPI Indicators with Conditional Formatting - Find most frequently purchased product or repeating names using formulas - Compare two lists and extract matching names in a new column - Create Abbreviations using TEXT functions - Build a final report with insights and storytelling Deliverable: - Well-structured workbook with multiple sheets (Raw Data, Analysis, Visualizations, Dashboard) - Summary Insights with key metrics: Total Revenue, Top Customers, Most Sold Products, Regional Sales - Use of all required formulas and functions as listed above

Sheet Pivot Analysis
A3: Sum of Total_Amount | B3: Category
A4: Region | B4: Appliances | C4: Electronics | D4: Furniture | E4: Grand Total
A5: Central | B5: 1999.71 | C5: 24889.33 | D5: 14399.3 | E5: 41288.34
A6: East | B6: 2239.67 | C6: 50649.01 | D6: 6399.71 | E6: 59288.39
A7: North | B7: 1119.84 | C7: 39239.04 | D7: 10449.43 | E7: 50808.31
A8: South | B8: 1099.83 | C8: 25549.32 | D8: 9749.6 | E8: 36398.75
A9: West | B9: 1879.69 | C9: 31429.35 | D9: 8099.64 | E9: 41408.68
A10: Grand Total | B10: 8338.74 | C10: 171756.05 | D10: 49097.68 | E10: 229192.47

Sheet Raw Data
A1: Transaction_ID | B1: Date | C1: Customer_ID | D1: Customer_Name | E1: Product_ID | F1: Product_Name | G1: Category | H1: Quantity | I1: Unit_Price | J1: Payment_Method | K1: Region | L1: Customer_Segment | M1: Customer_Since | N1: Total_Amount
A2: TRX0155 | B2: 45393 | C2: CUST023 | D2: Paul Baker | E2: P009 | F2: Monitor | G2: Electronics | H2: 3 | I2: 249.99 | J2: Cash | K2: Central | L2: Basic | M2: 44425 | N2: 749.97
A3: TRX0023 | B3: 45396 | C3: CUST013 | D3: Joseph Jackson | E3: P009 | F3: Monitor | G3: Electronics | H3: 3 | I3: 249.99 | J3: Credit Card | K3: Central | L3: Premium | M3: 44575 | N3: 749.97
A4: TRX0139 | B4: 45399 | C4: CUST021 | D4: Kevin Scott | E4: P005 | F4: Blender | G4: Appliances | H4: 3 | I4: 59.99 | J4: PayPal | K4: South | L4: Standard | M4: 45262 | N4: 179.97
A5: TRX0043 | B5: 45400 | C5: CUST046 | D5: Kathleen Bennett | E5: P005 | F5: Blender | G5: Appliances | H5: 3 | I5: 59.99 | J5: Cash | K5: North | L5: Premium | M5: 45114 | N5: 179.97
A6: TRX0212 | B6: 45400 | C6: CUST003 | D6: Michael Brown | E6: P008 | F6: Bookshelf | G6: Furniture | H6: 5 | I6: 149.99 | J6: Credit Card | K6: North | L6: Premium | M6: 45295 | N6: 749.95
A7: TRX0092 | B7: 45403 | C7: CUST024 | D7: Dorothy Nelson | E7: P005 | F7: Blender | G7: Appliances | H7: 2 | I7: 59.99 | J7: Cash | K7: West | L7: Standard | M7: 44746 | N7: 119.98
A8: TRX0193 | B8: 45403 | C8: CUST024 | D8: Dorothy Nelson | E8: P003 | F8: Headphones | G8: Electronics | H8: 5 | I8: 149.99 | J8: Credit Card | K8: Central | L8: Standard | M8: 44418 | N8: 749.95
A9: TRX0240 | B9: 45403 | C9: CUST017 | D9: Charles Allen | E9: P005 | F9: Blender | G9: Appliances | H9: 3 | I9: 59.99 | J9: Debit Card | K9: South | L9: Basic | M9: 45007 | N9: 179.97
A10: TRX0135 | B10: 45405 | C10: CUST009 | D10: Robert Thomas | E10: P001 | F10: Laptop | G10: Electronics | H10: 3 | I10: 899.99 | J10: PayPal | K10: East | L10: Standard | M10: 45299 | N10: 2699.97
A11: TRX0185 | B11: 45408 | C11: CUST026 | D11: Karen Hill | E11: P005 | F11: Blender | G11: Appliances | H11: 3 | I11: 59.99 | J11: Cash | K11: West | L11: Premium | M11: 45207 | N11: 179.97
A12: TRX0138 | B12: 45408 | C12: CUST022 | D12: Susan Green | E12: P008 | F12: Bookshelf | G12: Furniture | H12: 1 | I12: 149.99 | J12: Credit Card | K12: West | L12: Standard | M12: 45103 | N12: 149.99
A13: TRX0209 | B13: 45408 | C13: CUST046 | D13: Kathleen Bennett | E13: P008 | F13: Bookshelf | G13: Furniture | H13: 5 | I13: 149.99 | J13: Debit Card | K13: North | L13: Basic | M13: 44830 | N13: 749.95
... A251: TRX0064 | B251: 45758 | C251: CUST031 | D251: Steven Turner | E251: P010 | F251: Keyboard | G251: Electronics | H251: 3 | I251: 89.99 | J251: Debit Card | K251: North | L251: Premium | M251: 44878 | N251: 269.97

Sheet Monthly Trends
A3: Date | B3: Sum of Total_Amount
A4: 45718 | B4: 299.98
A5: 45720 | B5: 3499.95
A6: 45721 | B6: 299.95
A7: 45723 | B7: 1429.93
A8: 45724 | B8: 5399.89
A9: 45726 | B9: 249.99
A10: 45734 | B10: 119.98
A11: 45737 | B11: 5699.92
A12: 45739 | B12: 899.97
A13: 45740 | B13: 599.96
A14: 45743 | B14: 319.96
A15: 45745 | B15: 449.95
A16: 45746 | B16: 629.95
A17: Grand Total | B17: 19899.38

Sheet Detail1
A1: Details for Sum of Quantity - Product_Name: Smartphone
A3: Transaction_ID | B3: Date | C3: Customer_ID | D3: Customer_Name | E3: Product_ID | F3: Product_Name | G3: Category | H3: Quantity | I3: Unit_Price | J3: Payment_Method | K3: Region | L3: Customer_Segment | M3: Customer_Since | N3: Total_Amount
A4: TRX0120 | B4: 45758 | C4: CUST045 | D4: Douglas Watson | E4: P002 | F4: Smartphone | G4: Electronics | H4: 3 | I4: 699.99 | J4: PayPal | K4: North | L4: Basic | M4: 44909 | N4: 2099.97
A5: TRX0068 | B5: 45748 | C5: CUST044 | D5: Cynthia Price | E5: P002 | F5: Smartphone | G5: Electronics | H5: 2 | I5: 699.99 | J5: PayPal | K5: North | L5: Standard | M5: 44618 | N5: 1399.98
A6: TRX0226 | B6: 45720 | C6: CUST039 | D6: Lawrence Reed | E6: P002 | F6: Smartphone | G6: Electronics | H6: 5 | I6: 699.99 | J6: Debit Card | K6: East | L6: Premium | M6: 45161 | N6: 3499.95
A7: TRX0047 | B7: 45711 | C7: CUST042 | D7: Ruth Brooks | E7: P002 | F7: Smartphone | G7: Electronics | H7: 1 | I7: 699.99 | J7: Cash | K7: North | L7: Premium | M7: 44583 | N7: 699.99
A8: TRX0151 | B8: 45710 | C8: CUST040 | D8: Sharon Butler | E8: P002 | F8: Smartphone | G8: Electronics | H8: 1 | I8: 699.99 | J8: PayPal | K8: West | L8: Basic | M8: 44934 | N8: 699.99
A9: TRX0179 | B9: 45707 | C9: CUST029 | D9: Edward Mitchell | E9: P002 | F9: Smartphone | G9: Electronics | H9: 5 | I9: 699.99 | J9: PayPal | K9: South | L9: Premium | M9: 45352 | N9: 3499.95
A10: TRX0010 | B10: 45688 | C10: CUST026 | D10: Karen Hill | E10: P002 | F10: Smartphone | G10: Electronics | H10: 4 | I10: 699.99 | J10: Debit Card | K10: West | L10: Premium | M10: 44692 | N10: 2799.96
A11: TRX0188 | B11: 45686 | C11: CUST045 | D11: Douglas Watson | E11: P002 | F11: Smartphone | G11: Electronics | H11: 2 | I11: 699.99 | J11: Debit Card | K11: Central | L11: Premium | M11: 44681 | N11: 1399.98
A12: TRX0238 | B12: 45668 | C12: CUST038 | D12: Michelle Rogers | E12: P002 | F12: Smartphone | G12: Electronics | H12: 3 | I12: 699.99 | J12: Cash | K12: North | L12: Premium | M12: 44602 | N12: 2099.97
A13: TRX0125 | B13: 45666 | C13: CUST026 | D13: Karen Hill | E13: P002 | F13: Smartphone | G13: Electronics | H13: 3 | I13: 699.99 | J13: Credit Card | K13: Central | L13: Premium | M13: 45105 | N13: 2099.97
A14: TRX0066 | B14: 45630 | C14: CUST024 | D14: Dorothy Nelson | E14: P002 | F14: Smartphone | G14: Electronics | H14: 4 | I14: 699.99 | J14: Credit Card | K14: North | L14: Premium | M14: 44703 | N14: 2799.96
A15: TRX0201 | B15: 45627 | C15: CUST025 | D15: Mark Carter | E15: P002 | F15: Smartphone | G15: Electronics | H15: 5 | I15: 699.99 | J15: Debit Card | K15: West | L15: Standard | M15: 44944 | N15: 3499.95
... A34: TRX0015 | B34: 45440 | C34: CUST008 | D34: Jennifer Taylor | E34: P002 | F34: Smartphone | G34: Electronics | H34: 5 | I34: 699.99 | J34: PayPal | K34: West | L34: Standard | M34: 44407 | N34: 3499.95

Sheet Product Analysis Pivot
A3: Product_Name | B3: Sum of Total_Amount | C3: Sum of Quantity
A4: Bookshelf | B4: 15298.98 | C4: 102
A5: Smartphone | B5: 67199.04 | C5: 96
A6: Keyboard | B6: 8009.11 | C6: 89
A7: Monitor | B7: 21999.12 | C7: 88
A8: Blender | B8: 5219.13 | C8: 87
A9: Desk | B9: 23399.22 | C9: 78
A10: Laptop | B10: 67499.25 | C10: 75
A11: Office Chair | B11: 10399.48 | C11: 52
A12: Headphones | B12: 7049.53 | C12: 47
A13: Coffee Maker | B13: 3119.61 | C13: 39
A14: Grand Total | B14: 229192.47 | C14: 753

Sheet Analysis
A1: ANALYSIS – Customer Transactions
A2: Blue text on yellow = editable input. Black = formula. Every figure below is calculated from the 'Raw Data' sheet.
A3: Contents (click to jump)
A4: =HYPERLINK("#Analysis!A19","1. Summary Insights") -> 1. Summary Insights | D4: =HYPERLINK("#Analysis!A108","7. Customer Analysis") -> 7. Customer Analysis
A5: =HYPERLINK("#Analysis!A34","2. Date & Time Functions") -> 2. Date & Time Functions | D5: =HYPERLINK("#Analysis!A184","8. Compare Two Lists") -> 8. Compare Two Lists
A6: =HYPERLINK("#Analysis!A47","3. Monthly Sales Trend") -> 3. Monthly Sales Trend | D6: =HYPERLINK("#Analysis!A240","9. Timestamp with NOW() and Iterative Calculation") -> 9. Timestamp with NOW() and Iterative Calculation
A7: =HYPERLINK("#Analysis!A65","4. Regional Sales") -> 4. Regional Sales | D7: =HYPERLINK("#Analysis!A251","10. What-If Analysis") -> 10. What-If Analysis
A8: =HYPERLINK("#Analysis!A74","5. Category, Payment Method & Customer Segment Breakdowns") -> 5. Category, Payment Method & Customer Segment Breakdowns | D8: =HYPERLINK("#Analysis!A275","11. Linear Regression") -> 11. Linear Regression
A9: =HYPERLINK("#Analysis!A91","6. Product Analysis") -> 6. Product Analysis | D9: =HYPERLINK("#Analysis!A307","12. FILTER Function") -> 12. FILTER Function
A19: 1. Summary Insights – key metrics
A20: Metric | B20: Value | C20: Detail
A21: Total Revenue | B21: =SUM(rdAmt) -> 229192.47
A22: Total Transactions | B22: =COUNTA(rdID) -> 250
A23: Units Sold | B23: =SUM(rdQty) -> 753
A24: Average Order Value | B24: =B21/B22 -> 916.76988
A25: Unique Customers | B25: =COUNTIF(E112:E161,">0") -> 50
A26: Top Customer | B26: =INDEX(B112:B161,MATCH(1,K112:K161,0)) -> Mark Carter | C26: =TEXT(INDEX(F112:F161,MATCH(1,K112:K161,0)),"[>=10000000]\₹##\,##\,##\,##0.00;[>=100000]\₹##\,##\,##0.00;\₹#,##0.00")&" total spend" -> ₹15,659.65 total spend
A27: Most Sold Product (units) | B27: =B104 -> Bookshelf | C27: =TEXT(C104,"0")&" units" -> 102 units
A28: Most Frequently Purchased Product | B28: =B106 -> Bookshelf | C28: =TEXT(C106,"0")&" transactions" -> 35 transactions
A29: Top Region | B29: =INDEX(A67:A71,MATCH(1,H67:H71,0)) -> East | C29: =TEXT(INDEX(C67:C71,MATCH(1,H67:H71,0)),"[>=10000000]\₹##\,##\,##\,##0.00;[>=100000]\₹##\,##\,##0.00;\₹#,##0.00")&" revenue" -> ₹59,288.39 revenue
A30: Lowest Region | B30: =INDEX(A67:A71,MATCH(5,H67:H71,0)) -> South | C30: =TEXT(INDEX(C67:C71,MATCH(5,H67:H71,0)),"[>=10000000]\₹##\,##\,##\,##0.00;[>=100000]\₹##\,##\,##0.00;\₹#,##0.00")&" revenue" -> ₹36,398.75 revenue
A31: Peak Month | B31: =INDEX(A49:A61,MATCH(MAX(D49:D61),D49:D61,0)) -> Jan 2025 | C31: =TEXT(MAX(D49:D61),"[>=10000000]\₹##\,##\,##\,##0.00;[>=100000]\₹##\,##\,##0.00;\₹#,##0.00")&" revenue" -> ₹25,799.15 revenue
A34: 2. Date & Time Functions (TODAY, NOW, DATEDIF, EOMONTH)
A35: Metric | B35: Value | C35: Function used
A36: Today's date | B36: =TODAY() -> 46310 | C36: TODAY
A37: Current date & time | B37: =NOW() -> 46310.996 | C37: NOW
A38: First transaction date | B38: =MIN(rdDate) -> 45393 | C38: MIN
A39: Last transaction date | B39: =MAX(rdDate) -> 45758 | C39: MAX
A40: Dataset span (years / months / days) | B40: =DATEDIF(B38,B39,"y")&" yr "&DATEDIF(B38,B39,"ym")&" mo "&DATEDIF(B38,B39,"md")&" d" -> 1 yr 0 mo 0 d | C40: DATEDIF y / ym / md
A41: Days covered by the dataset | B41: =B39-B38 -> 365 | C41: Date subtraction
A42: Month-end of last transaction | B42: =EOMONTH(B39,0) -> 45777 | C42: EOMONTH
A43: End of the current month | B43: =EOMONTH(TODAY(),0) -> 46326 | C43: EOMONTH
A44: Days left in the current month | B44: =EOMONTH(TODAY(),0)-TODAY() -> 16 | C44: EOMONTH, TODAY
A45: Months since last transaction | B45: =DATEDIF(B39,TODAY(),"m") -> 18 | C45: DATEDIF m
A47: 3. Monthly Sales Trend (EOMONTH, SUMIFS, arrow icons)
A48: Month | B48: Month start | C48: Month end (EOMONTH) | D48: Revenue | E48: Transactions | F48: Units sold | G48: MoM change | H48: Cumulative revenue
A49: =TEXT(B49,"mmm yyyy") -> Apr 2024 | B49: =EOMONTH(MIN(rdDate),-1)+1 -> 45383 | C49: =EOMONTH(B49,0) -> 45412 | D49: =SUMIFS(rdAmt,rdDate,">="&B49,rdDate,"<="&C49) -> 20919.33 | E49: =COUNTIFS(rdDate,">="&B49,rdDate,"<="&C49) -> 21 | F49: =SUMIFS(rdQty,rdDate,">="&B49,rdDate,"<="&C49) -> 67 | H49: =SUM(D$49:D49) -> 20919.33
A50: =TEXT(B50,"mmm yyyy") -> May 2024 | B50: =EOMONTH(B49,0)+1 -> 45413 | C50: =EOMONTH(B50,0) -> 45443 | D50: =SUMIFS(rdAmt,rdDate,">="&B50,rdDate,"<="&C50) -> 17039.35 | E50: =COUNTIFS(rdDate,">="&B50,rdDate,"<="&C50) -> 19 | F50: =SUMIFS(rdQty,rdDate,">="&B50,rdDate,"<="&C50) -> 65 | G50: =IF(D49=0,0,D50/D49-1) -> -0.18547344 | H50: =SUM(D$49:D50) -> 37958.68
A51: =TEXT(B51,"mmm yyyy") -> Jun 2024 | B51: =EOMONTH(B50,0)+1 -> 45444 | C51: =EOMONTH(B51,0) -> 45473 | D51: =SUMIFS(rdAmt,rdDate,">="&B51,rdDate,"<="&C51) -> 19299.45 | E51: =COUNTIFS(rdDate,">="&B51,rdDate,"<="&C51) -> 19 | F51: =SUMIFS(rdQty,rdDate,">="&B51,rdDate,"<="&C51) -> 55 | G51: =IF(D50=0,0,D51/D50-1) -> 0.13264004 | H51: =SUM(D$49:D51) -> 57258.13
A52: =TEXT(B52,"mmm yyyy") -> Jul 2024 | B52: =EOMONTH(B51,0)+1 -> 45474 | C52: =EOMONTH(B52,0) -> 45504 | D52: =SUMIFS(rdAmt,rdDate,">="&B52,rdDate,"<="&C52) -> 18479.4 | E52: =COUNTIFS(rdDate,">="&B52,rdDate,"<="&C52) -> 24 | F52: =SUMIFS(rdQty,rdDate,">="&B52,rdDate,"<="&C52) -> 60 | G52: =IF(D51=0,0,D52/D51-1) -> -0.042490848 | H52: =SUM(D$49:D52) -> 75737.53
...

Sheet Visualizations
A1: VISUALIZATIONS – Pivot-style tables and charts
A2: Each table is a formula-driven pivot (SUMIFS on the Raw Data); each chart reads straight from its table.
A4: Pivot Table 1 – Revenue by Region × Category
A5: Region | B5: Appliances | C5: Electronics | D5: Furniture | E5: Grand Total
A6: Central | B6: =SUMIFS(rdAmt,rdReg,$A6,rdCat,B$5) -> 1999.71 | C6: =SUMIFS(rdAmt,rdReg,$A6,rdCat,C$5) -> 24889.33 | D6: =SUMIFS(rdAmt,rdReg,$A6,rdCat,D$5) -> 14399.3 | E6: =SUM(B6:D6) -> 41288.34
A7: East | B7: =SUMIFS(rdAmt,rdReg,$A7,rdCat,B$5) -> 2239.67 | C7: =SUMIFS(rdAmt,rdReg,$A7,rdCat,C$5) -> 50649.01 | D7: =SUMIFS(rdAmt,rdReg,$A7,rdCat,D$5) -> 6399.71 | E7: =SUM(B7:D7) -> 59288.39
A8: North | B8: =SUMIFS(rdAmt,rdReg,$A8,rdCat,B$5) -> 1119.84 | C8: =SUMIFS(rdAmt,rdReg,$A8,rdCat,C$5) -> 39239.04 | D8: =SUMIFS(rdAmt,rdReg,$A8,rdCat,D$5) -> 10449.43 | E8: =SUM(B8:D8) -> 50808.31
A9: South | B9: =SUMIFS(rdAmt,rdReg,$A9,rdCat,B$5) -> 1099.83 | C9: =SUMIFS(rdAmt,rdReg,$A9,rdCat,C$5) -> 25549.32 | D9: =SUMIFS(rdAmt,rdReg,$A9,rdCat,D$5) -> 9749.6 | E9: =SUM(B9:D9) -> 36398.75
A10: West | B10: =SUMIFS(rdAmt,rdReg,$A10,rdCat,B$5) -> 1879.69 | C10: =SUMIFS(rdAmt,rdReg,$A10,rdCat,C$5) -> 31429.35 | D10: =SUMIFS(rdAmt,rdReg,$A10,rdCat,D$5) -> 8099.64 | E10: =SUM(B10:D10) -> 41408.68
A11: Grand Total | B11: =SUM(B6:B10) -> 8338.74 | C11: =SUM(C6:C10) -> 171756.05 | D11: =SUM(D6:D10) -> 49097.68 | E11: =SUM(E6:E10) -> 229192.47
A24: Pivot Table 2 – Monthly Revenue & Transactions
A25: Month | B25: Revenue | C25: Transactions | D25: Units
A26: =Analysis!A49 -> Apr 2024 | B26: =SUMIFS(rdAmt,rdDate,">="&Analysis!B49,rdDate,"<="&Analysis!C49) -> 20919.33 | C26: =COUNTIFS(rdDate,">="&Analysis!B49,rdDate,"<="&Analysis!C49) -> 21 | D26: =SUMIFS(rdQty,rdDate,">="&Analysis!B49,rdDate,"<="&Analysis!C49) -> 67
A27: =Analysis!A50 -> May 2024 | B27: =SUMIFS(rdAmt,rdDate,">="&Analysis!B50,rdDate,"<="&Analysis!C50) -> 17039.35 | C27: =COUNTIFS(rdDate,">="&Analysis!B50,rdDate,"<="&Analysis!C50) -> 19 | D27: =SUMIFS(rdQty,rdDate,">="&Analysis!B50,rdDate,"<="&Analysis!C50) -> 65
A28: =Analysis!A51 -> Jun 2024 | B28: =SUMIFS(rdAmt,rdDate,">="&Analysis!B51,rdDate,"<="&Analysis!C51) -> 19299.45 | C28: =COUNTIFS(rdDate,">="&Analysis!B51,rdDate,"<="&Analysis!C51) -> 19 | D28: =SUMIFS(rdQty,rdDate,">="&Analysis!B51,rdDate,"<="&Analysis!C51) -> 55
A29: =Analysis!A52 -> Jul 2024 | B29: =SUMIFS(rdAmt,rdDate,">="&Analysis!B52,rdDate,"<="&Analysis!C52) -> 18479.4 | C29: =COUNTIFS(rdDate,">="&Analysis!B52,rdDate,"<="&Analysis!C52) -> 24 | D29: =SUMIFS(rdQty,rdDate,">="&Analysis!B52,rdDate,"<="&Analysis!C52) -> 60
A30: =Analysis!A53 -> Aug 2024 | B30: =SUMIFS(rdAmt,rdDate,">="&Analysis!B53,rdDate,"<="&Analysis!C53) -> 15759.43 | C30: =COUNTIFS(rdDate,">="&Analysis!B53,rdDate,"<="&Analysis!C53) -> 18 | D30: =SUMIFS(rdQty,rdDate,">="&Analysis!B53,rdDate,"<="&Analysis!C53) -> 57
A31: =Analysis!A54 -> Sep 2024 | B31: =SUMIFS(rdAmt,rdDate,">="&Analysis!B54,rdDate,"<="&Analysis!C54) -> 12989.51 | C31: =COUNTIFS(rdDate,">="&Analysis!B54,rdDate,"<="&Analysis!C54) -> 19 | D31: =SUMIFS(rdQty,rdDate,">="&Analysis!B54,rdDate,"<="&Analysis!C54) -> 49
A32: =Analysis!A55 -> Oct 2024 | B32: =SUMIFS(rdAmt,rdDate,">="&Analysis!B55,rdDate,"<="&Analysis!C55) -> 20609.52 | C32: =COUNTIFS(rdDate,">="&Analysis!B55,rdDate,"<="&Analysis!C55) -> 16 | D32: =SUMIFS(rdQty,rdDate,">="&Analysis!B55,rdDate,"<="&Analysis!C55) -> 48
A33: =Analysis!A56 -> Nov 2024 | B33: =SUMIFS(rdAmt,rdDate,">="&Analysis!B56,rdDate,"<="&Analysis!C56) -> 12309.44 | C33: =COUNTIFS(rdDate,">="&Analysis!B56,rdDate,"<="&Analysis!C56) -> 17 | D33: =SUMIFS(rdQty,rdDate,">="&Analysis!B56,rdDate,"<="&Analysis!C56) -> 56
A34: =Analysis!A57 -> Dec 2024 | B34: =SUMIFS(rdAmt,rdDate,">="&Analysis!B57,rdDate,"<="&Analysis!C57) -> 23039.3 | C34: =COUNTIFS(rdDate,">="&Analysis!B57,rdDate,"<="&Analysis!C57) -> 25 | D34: =SUMIFS(rdQty,rdDate,">="&Analysis!B57,rdDate,"<="&Analysis!C57) -> 70
A35: =Analysis!A58 -> Jan 2025 | B35: =SUMIFS(rdAmt,rdDate,">="&Analysis!B58,rdDate,"<="&Analysis!C58) -> 25799.15 | C35: =COUNTIFS(rdDate,">="&Analysis!B58,rdDate,"<="&Analysis!C58) -> 26 | D35: =SUMIFS(rdQty,rdDate,">="&Analysis!B58,rdDate,"<="&Analysis!C58) -> 85
A36: =Analysis!A59 -> Feb 2025 | B36: =SUMIFS(rdAmt,rdDate,">="&Analysis!B59,rdDate,"<="&Analysis!C59) -> 16069.38 | C36: =COUNTIFS(rdDate,">="&Analysis!B59,rdDate,"<="&Analysis!C59) -> 20 | D36: =SUMIFS(rdQty,rdDate,">="&Analysis!B59,rdDate,"<="&Analysis!C59) -> 62
A37: =Analysis!A60 -> Mar 2025 | B37: =SUMIFS(rdAmt,rdDate,">="&Analysis!B60,rdDate,"<="&Analysis!C60) -> 19899.38 | C37: =COUNTIFS(rdDate,">="&Analysis!B60,rdDate,"<="&Analysis!C60) -> 19 | D37: =SUMIFS(rdQty,rdDate,">="&Analysis!B60,rdDate,"<="&Analysis!C60) -> 62
A38: =Analysis!A61 -> Apr 2025 | B38: =SUMIFS(rdAmt,rdDate,">="&Analysis!B61,rdDate,"<="&Analysis!C61) -> 6979.83 | C38: =COUNTIFS(rdDate,">="&Analysis!B61,rdDate,"<="&Analysis!C61) -> 7 | D38: =SUMIFS(rdQty,rdDate,">="&Analysis!B61,rdDate,"<="&Analysis!C61) -> 17
A39: Grand Total | B39: =SUM(B26:B38) -> 229192.47 | C39: =SUM(C26:C38) -> 250 | D39: =SUM(D26:D38) -> 753
A44: Pivot Table 3 – Revenue by Category
A45: Category | B45: Revenue | C45: Share
A46: Electronics | B46: =SUMIFS(rdAmt,rdCat,A46) -> 171756.05 | C46: =B46/SUM(B$46:B$48) -> 0.74939657
A47: Furniture | B47: =SUMIFS(rdAmt,rdCat,A47) -> 49097.68 | C47: =B47/SUM(B$46:B$48) -> 0.2142203
A48: Appliances | B48: =SUMIFS(rdAmt,rdCat,A48) -> 8338.74 | C48: =B48/SUM(B$46:B$48) -> 0.036383132
A49: Grand Total | B49: =SUM(B46:B48) -> 229192.47 | C49: =SUM(C46:C48) -> 1
A64: Pivot Table 4 – Top 10 Customers by Spend
A65: Customer | B65: Total spend | C65: Share
A66: =Analysis!B172 -> Mark Carter | B66: =Analysis!C172 -> 15659.65 | C66: =Analysis!D172 -> 0.068325325
A67: =Analysis!B173 -> Edward Mitchell | B67: =Analysis!C173 -> 11919.77 | C67: =Analysis!D173 -> 0.052007686
A68: =Analysis!B174 -> Barbara Young | B68: =Analysis!C174 -> 10649.8 | C68: =Analysis!D174 -> 0.046466623
A69: =Analysis!B175 -> Patricia Moore | B69: =Analysis!C175 -> 9799.73 | C69: =Analysis!D175 -> 0.042757644
A70: =Analysis!B176 -> Paul Baker | B70: =Analysis!C176 -> 8309.74 | C70: =Analysis!D176 -> 0.036256601
A71: =Analysis!B177 -> Dorothy Nelson | B71: =Analysis!C177 -> 8269.79 | C71: =Analysis!D177 -> 0.036082294
...

Sheet Dashboard
A1: Data Intelligence Dashboard
A2: ="Customer transactions "&TEXT(MIN(rdDate),"dd mmm yyyy")&" – "&TEXT(MAX(rdDate),"dd mmm yyyy")&" | Region: "&$B$4&" | Category: "&$D$4&" | "&TEXT($F$4,"dd mmm yy")&" to "&TEXT($H$4,"dd mmm yy") -> Customer transactions 11 Apr 2024 – 11 Apr 2025 | Region: All | Category: All | 01 Apr 24 to 30 Apr 25
A3: Slicers & timeline – change the yellow cells
A4: Region slicer | B4: All | C4: Category slicer | D4: All | E4: Timeline: from | F4: 45383 | G4: to | H4: 45777
A6: TOTAL REVENUE | C6: TRANSACTIONS | E6: UNITS SOLD | G6: AVG ORDER VALUE | I6: ACTIVE CUSTOMERS | K6: UNITS PER ORDER
A7: =SUMIFS(rdAmt,rdReg,$B$54,rdCat,$B$55,rdDate,">="&$F$4,rdDate,"<="&$H$4) -> 229192.47 | C7: =COUNTIFS(rdReg,$B$54,rdCat,$B$55,rdDate,">="&$F$4,rdDate,"<="&$H$4) -> 250 | E7: =SUMIFS(rdQty,rdReg,$B$54,rdCat,$B$55,rdDate,">="&$F$4,rdDate,"<="&$H$4) -> 753 | G7: =IF(C7=0,0,A7/C7) -> 916.76988 | I7: =SUMPRODUCT(--(COUNTIFS(rdCustID,Analysis!$A$112:$A$161,rdReg,$B$54,rdCat,$B$55,rdDate,">="&$F$4,rdDate,"<="&$H$4)>0)) -> 50 | K7: =IF(C7=0,0,E7/C7) -> 3.012
A8: =IF(Analysis!$B$21=0,0,A7/Analysis!$B$21) -> 1 | C8: =IF(Analysis!$B$22=0,0,C7/Analysis!$B$22) -> 1 | E8: =IF(Analysis!$B$23=0,0,E7/Analysis!$B$23) -> 1 | G8: =IF(Analysis!$B$24=0,0,G7/Analysis!$B$24-1) -> 0 | I8: =IF(Analysis!$B$25=0,0,I7/Analysis!$B$25) -> 1 | K8: =IF(Analysis!$B$23=0,0,K7/(Analysis!$B$23/Analysis!$B$22)-1) -> 0
A9: KPI icons: arrows compare with the overall dataset; traffic lights show share of the overall total (red < 15%, amber 15–30%, green ≥ 30%).
A11: Region scorecard (respects Category & timeline) | G11: Top 5 customers (respects all filters)
A12: Region | B12: Revenue | C12: Share | D12: vs avg region | G12: Rank | H12: Customer | K12: Spend | L12: Share
A13: Central | B13: =SUMIFS(rdAmt,rdReg,A13,rdCat,$B$55,rdDate,">="&$F$4,rdDate,"<="&$H$4) -> 41288.34 | C13: =IF(SUM(B$13:B$17)=0,0,B13/SUM(B$13:B$17)) -> 0.18014702 | D13: =IF(AVERAGE(B$13:B$17)=0,0,B13/AVERAGE(B$13:B$17)-1) -> -0.09926491 | G13: 1 | H13: =IF(K13=0,"",INDEX($B$82:$B$131,MATCH(LARGE($D$82:$D$131,G13),$D$82:$D$131,0))) -> Mark Carter | K13: =ROUND(LARGE($D$82:$D$131,G13),2) -> 15659.65 | L13: =IF($A$7=0,0,K13/$A$7) -> 0.068325325
A14: East | B14: =SUMIFS(rdAmt,rdReg,A14,rdCat,$B$55,rdDate,">="&$F$4,rdDate,"<="&$H$4) -> 59288.39 | C14: =IF(SUM(B$13:B$17)=0,0,B14/SUM(B$13:B$17)) -> 0.25868385 | D14: =IF(AVERAGE(B$13:B$17)=0,0,B14/AVERAGE(B$13:B$17)-1) -> 0.29341924 | G14: 2 | H14: =IF(K14=0,"",INDEX($B$82:$B$131,MATCH(LARGE($D$82:$D$131,G14),$D$82:$D$131,0))) -> Edward Mitchell | K14: =ROUND(LARGE($D$82:$D$131,G14),2) -> 11919.77 | L14: =IF($A$7=0,0,K14/$A$7) -> 0.052007686
A15: North | B15: =SUMIFS(rdAmt,rdReg,A15,rdCat,$B$55,rdDate,">="&$F$4,rdDate,"<="&$H$4) -> 50808.31 | C15: =IF(SUM(B$13:B$17)=0,0,B15/SUM(B$13:B$17)) -> 0.22168403 | D15: =IF(AVERAGE(B$13:B$17)=0,0,B15/AVERAGE(B$13:B$17)-1) -> 0.10842014 | G15: 3 | H15: =IF(K15=0,"",INDEX($B$82:$B$131,MATCH(LARGE($D$82:$D$131,G15),$D$82:$D$131,0))) -> Barbara Young | K15: =ROUND(LARGE($D$82:$D$131,G15),2) -> 10649.8 | L15: =IF($A$7=0,0,K15/$A$7) -> 0.046466623
A16: South | B16: =SUMIFS(rdAmt,rdReg,A16,rdCat,$B$55,rdDate,">="&$F$4,rdDate,"<="&$H$4) -> 36398.75 | C16: =IF(SUM(B$13:B$17)=0,0,B16/SUM(B$13:B$17)) -> 0.15881303 | D16: =IF(AVERAGE(B$13:B$17)=0,0,B16/AVERAGE(B$13:B$17)-1) -> -0.20593486 | G16: 4 | H16: =IF(K16=0,"",INDEX($B$82:$B$131,MATCH(LARGE($D$82:$D$131,G16),$D$82:$D$131,0))) -> Patricia Moore | K16: =ROUND(LARGE($D$82:$D$131,G16),2) -> 9799.73 | L16: =IF($A$7=0,0,K16/$A$7) -> 0.042757644
A17: West | B17: =SUMIFS(rdAmt,rdReg,A17,rdCat,$B$55,rdDate,">="&$F$4,rdDate,"<="&$H$4) -> 41408.68 | C17: =IF(SUM(B$13:B$17)=0,0,B17/SUM(B$13:B$17)) -> 0.18067208 | D17: =IF(AVERAGE(B$13:B$17)=0,0,B17/AVERAGE(B$13:B$17)-1) -> -0.096639606 | G17: 5 | H17: =IF(K17=0,"",INDEX($B$82:$B$131,MATCH(LARGE($D$82:$D$131,G17),$D$82:$D$131,0))) -> Paul Baker | K17: =ROUND(LARGE($D$82:$D$131,G17),2) -> 8309.74 | L17: =IF($A$7=0,0,K17/$A$7) -> 0.036256601
A18: Total | B18: =SUM(B13:B17) -> 229192.47
A53: Chart data & helpers (formulas – feed the dashboard)
A54: Region criteria | B54: =IF($B$4="All","*",$B$4) -> *
A55: Category criteria | B55: =IF($D$4="All","*",$D$4) -> *
A57: Month | B57: Revenue | D57: Category | E57: Revenue | G57: Product ID | H57: Product | I57: Units | J57: Sort key
A58: =Analysis!A49 -> Apr 2024 | B58: =SUMIFS(rdAmt,rdReg,$B$54,rdCat,$B$55,rdDate,">="&MAX(Analysis!B49,$F$4),rdDate,"<="&MIN(Analysis!C49,$H$4)) -> 20919.33 | D58: Electronics | E58: =SUMIFS(rdAmt,rdCat,D58,rdReg,$B$54,rdDate,">="&$F$4,rdDate,"<="&$H$4) -> 171756.05 | G58: =Analysis!A93 -> P001 | H58: =Analysis!B93 -> Laptop | I58: =SUMIFS(rdQty,rdProdID,G58,rdReg,$B$54,rdCat,$B$55,rdDate,">="&$F$4,rdDate,"<="&$H$4) -> 75 | J58: =I58+(100-ROWS(J$58:J58))/100000 -> 75.00099
A59: =Analysis!A50 -> May 2024 | B59: =SUMIFS(rdAmt,rdReg,$B$54,rdCat,$B$55,rdDate,">="&MAX(Analysis!B50,$F$4),rdDate,"<="&MIN(Analysis!C50,$H$4)) -> 17039.35 | D59: Furniture | E59: =SUMIFS(rdAmt,rdCat,D59,rdReg,$B$54,rdDate,">="&$F$4,rdDate,"<="&$H$4) -> 49097.68 | G59: =Analysis!A94 -> P002 | H59: =Analysis!B94 -> Smartphone | I59: =SUMIFS(rdQty,rdProdID,G59,rdReg,$B$54,rdCat,$B$55,rdDate,">="&$F$4,rdDate,"<="&$H$4) -> 96 | J59: =I59+(100-ROWS(J$58:J59))/100000 -> 96.00098
A60: =Analysis!A51 -> Jun 2024 | B60: =SUMIFS(rdAmt,rdReg,$B$54,rdCat,$B$55,rdDate,">="&MAX(Analysis!B51,$F$4),rdDate,"<="&MIN(Analysis!C51,$H$4)) -> 19299.45 | D60: Appliances | E60: =SUMIFS(rdAmt,rdCat,D60,rdReg,$B$54,rdDate,">="&$F$4,rdDate,"<="&$H$4) -> 8338.74 | G60: =Analysis!A95 -> P003 | H60: =Analysis!B95 -> Headphones | I60: =SUMIFS(rdQty,rdProdID,G60,rdReg,$B$54,rdCat,$B$55,rdDate,">="&$F$4,rdDate,"<="&$H$4) -> 47 | J60: =I60+(100-ROWS(J$58:J60))/100000 -> 47.00097
A61: =Analysis!A52 -> Jul 2024 | B61: =SUMIFS(rdAmt,rdReg,$B$54,rdCat,$B$55,rdDate,">="&MAX(Analysis!B52,$F$4),rdDate,"<="&MIN(Analysis!C52,$H$4)) -> 18479.4 | G61: =Analysis!A96 -> P004 | H61: =Analysis!B96 -> Coffee Maker | I61: =SUMIFS(rdQty,rdProdID,G61,rdReg,$B$54,rdCat,$B$55,rdDate,">="&$F$4,rdDate,"<="&$H$4) -> 39 | J61: =I61+(100-ROWS(J$58:J61))/100000 -> 39.00096
A62: =Analysis!A53 -> Aug 2024 | B62: =SUMIFS(rdAmt,rdReg,$B$54,rdCat,$B$55,rdDate,">="&MAX(Analysis!B53,$F$4),rdDate,"<="&MIN(Analysis!C53,$H$4)) -> 15759.43 | G62: =Analysis!A97 -> P005 | H62: =Analysis!B97 -> Blender | I62: =SUMIFS(rdQty,rdProdID,G62,rdReg,$B$54,rdCat,$B$55,rdDate,">="&$F$4,rdDate,"<="&$H$4) -> 87 | J62: =I62+(100-ROWS(J$58:J62))/100000 -> 87.00095
A63: =Analysis!A54 -> Sep 2024 | B63: =SUMIFS(rdAmt,rdReg,$B$54,rdCat,$B$55,rdDate,">="&MAX(Analysis!B54,$F$4),rdDate,"<="&MIN(Analysis!C54,$H$4)) -> 12989.51 | G63: =Analysis!A98 -> P006 | H63: =Analysis!B98 -> Office Chair | I63: =SUMIFS(rdQty,rdProdID,G63,rdReg,$B$54,rdCat,$B$55,rdDate,">="&$F$4,rdDate,"<="&$H$4) -> 52 | J63: =I63+(100-ROWS(J$58:J63))/100000 -> 52.00094
A64: =Analysis!A55 -> Oct 2024 | B64: =SUMIFS(rdAmt,rdReg,$B$54,rdCat,$B$55,rdDate,">="&MAX(Analysis!B55,$F$4),rdDate,"<="&MIN(Analysis!C55,$H$4)) -> 20609.52 | G64: =Analysis!A99 -> P007 | H64: =Analysis!B99 -> Desk | I64: =SUMIFS(rdQty,rdProdID,G64,rdReg,$B$54,rdCat,$B$55,rdDate,">="&$F$4,rdDate,"<="&$H$4) -> 78 | J64: =I64+(100-ROWS(J$58:J64))/100000 -> 78.00093
A65: =Analysis!A56 -> Nov 2024 | B65: =SUMIFS(rdAmt,rdReg,$B$54,rdCat,$B$55,rdDate,">="&MAX(Analysis!B56,$F$4),rdDate,"<="&MIN(Analysis!C56,$H$4)) -> 12309.44 | G65: =Analysis!A100 -> P008 | H65: =Analysis!B100 -> Bookshelf | I65: =SUMIFS(rdQty,rdProdID,G65,rdReg,$B$54,rdCat,$B$55,rdDate,">="&$F$4,rdDate,"<="&$H$4) -> 102 | J65: =I65+(100-ROWS(J$58:J65))/100000 -> 102.00092
A66: =Analysis!A57 -> Dec 2024 | B66: =SUMIFS(rdAmt,rdReg,$B$54,rdCat,$B$55,rdDate,">="&MAX(Analysis!B57,$F$4),rdDate,"<="&MIN(Analysis!C57,$H$4)) -> 23039.3 | G66: =Analysis!A101 -> P009 | H66: =Analysis!B101 -> Monitor | I66: =SUMIFS(rdQty,rdProdID,G66,rdReg,$B$54,rdCat,$B$55,rdDate,">="&$F$4,rdDate,"<="&$H$4) -> 88 | J66: =I66+(100-ROWS(J$58:J66))/100000 -> 88.00091
A67: =Analysis!A58 -> Jan 2025 | B67: =SUMIFS(rdAmt,rdReg,$B$54,rdCat,$B$55,rdDate,">="&MAX(Analysis!B58,$F$4),rdDate,"<="&MIN(Analysis!C58,$H$4)) -> 25799.15 | G67: =Analysis!A102 -> P010 | H67: =Analysis!B102 -> Keyboard | I67: =SUMIFS(rdQty,rdProdID,G67,rdReg,$B$54,rdCat,$B$55,rdDate,">="&$F$4,rdDate,"<="&$H$4) -> 89 | J67: =I67+(100-ROWS(J$58:J67))/100000 -> 89.0009
A68: =Analysis!A59 -> Feb 2025 | B68: =SUMIFS(rdAmt,rdReg,$B$54,rdCat,$B$55,rdDate,">="&MAX(Analysis!B59,$F$4),rdDate,"<="&MIN(Analysis!C59,$H$4)) -> 16069.38
A69: =Analysis!A60 -> Mar 2025 | B69: =SUMIFS(rdAmt,rdReg,$B$54,rdCat,$B$55,rdDate,">="&MAX(Analysis!B60,$F$4),rdDate,"<="&MIN(Analysis!C60,$H$4)) -> 19899.38
A70: =Analysis!A61 -> Apr 2025 | B70: =SUMIFS(rdAmt,rdReg,$B$54,rdCat,$B$55,rdDate,">="&MAX(Analysis!B61,$F$4),rdDate,"<="&MIN(Analysis!C61,$H$4)) -> 6979.83
A74: Product (top 5) | B74: Units
A75: =INDEX($H$58:$H$67,MATCH(LARGE($J$58:$J$67,1),$J$58:$J$67,0)) -> Bookshelf | B75: =INDEX($I$58:$I$67,MATCH(LARGE($J$58:$J$67,1),$J$58:$J$67,0)) -> 102
A76: =INDEX($H$58:$H$67,MATCH(LARGE($J$58:$J$67,2),$J$58:$J$67,0)) -> Smartphone | B76: =INDEX($I$58:$I$67,MATCH(LARGE($J$58:$J$67,2),$J$58:$J$67,0)) -> 96
A77: =INDEX($H$58:$H$67,MATCH(LARGE($J$58:$J$67,3),$J$58:$J$67,0)) -> Keyboard | B77: =INDEX($I$58:$I$67,MATCH(LARGE($J$58:$J$67,3),$J$58:$J$67,0)) -> 89
A78: =INDEX($H$58:$H$67,MATCH(LARGE($J$58:$J$67,4),$J$58:$J$67,0)) -> Monitor | B78: =INDEX($I$58:$I$67,MATCH(LARGE($J$58:$J$67,4),$J$58:$J$67,0)) -> 88
A79: =INDEX($H$58:$H$67,MATCH(LARGE($J$58:$J$67,5),$J$58:$J$67,0)) -> Blender | B79: =INDEX($I$58:$I$67,MATCH(LARGE($J$58:$J$67,5),$J$58:$J$67,0)) -> 87
A81: Customer ID | B81: Customer | C81: Transactions | D81: Spend (filtered + sort key)
...

Sheet Final Report
B1: FINAL REPORT – Insights & Storytelling
B2: ="Prepared "&TEXT(TODAY(),"dd mmmm yyyy")&" from "&TEXT(COUNTA(rdID),"#,##0")&" customer transactions ("&TEXT(MIN(rdDate),"dd mmm yyyy")&" – "&TEXT(MAX(rdDate),"dd mmm yyyy")&")" -> Prepared 15 October 2026 from 250 customer transactions (11 Apr 2024 – 11 Apr 2025)
B4: 1. The headline
B5: ="Over the period the business booked "&TEXT(Analysis!$B$21,"[>=10000000]\₹##\,##\,##\,##0;[>=100000]\₹##\,##\,##0;\₹#,##0")&" in revenue across "&TEXT(Analysis!$B$22,"#,##0")&" transactions, selling "&TEXT(Analysis!$B$23,"#,##0")&" units to "&Analysis!$B$25&" customers. The average order was worth "&TEXT(Analysis!$B$24,"[>=10000000]\₹##\,##\,##\,##0.00;[>=100000]\₹##\,##\,##0.00;\₹#,##0.00")&"." -> Over the period the business booked ₹2,29,192 in revenue across 250 transactions, selling 753 units to 50 customers. The average order was worth ₹916.77.
B7: 2. Key metrics
B8: Metric | C8: Value
B9: Total Revenue | C9: =Analysis!$B$21 -> 229192.47
B10: Transactions | C10: =Analysis!$B$22 -> 250
B11: Units sold | C11: =Analysis!$B$23 -> 753
B12: Average order value | C12: =Analysis!$B$24 -> 916.76988
B13: Top customer | C13: =Analysis!$B$26 -> Mark Carter
B14: Most sold product | C14: =Analysis!$B$104 -> Bookshelf
B15: Top region | C15: =Analysis!$B$29 -> East
B17: Top 5 customers | E17: Most sold products
B18: Customer | C18: Total spend | E18: Product | F18: Units
B19: =Analysis!B172 -> Mark Carter | C19: =Analysis!C172 -> 15659.65 | E19: =INDEX(Analysis!$B$93:$B$102,MATCH(1,Analysis!$H$93:$H$102,0)) -> Bookshelf | F19: =INDEX(Analysis!$E$93:$E$102,MATCH(1,Analysis!$H$93:$H$102,0)) -> 102
B20: =Analysis!B173 -> Edward Mitchell | C20: =Analysis!C173 -> 11919.77 | E20: =INDEX(Analysis!$B$93:$B$102,MATCH(2,Analysis!$H$93:$H$102,0)) -> Smartphone | F20: =INDEX(Analysis!$E$93:$E$102,MATCH(2,Analysis!$H$93:$H$102,0)) -> 96
B21: =Analysis!B174 -> Barbara Young | C21: =Analysis!C174 -> 10649.8 | E21: =INDEX(Analysis!$B$93:$B$102,MATCH(3,Analysis!$H$93:$H$102,0)) -> Keyboard | F21: =INDEX(Analysis!$E$93:$E$102,MATCH(3,Analysis!$H$93:$H$102,0)) -> 89
B22: =Analysis!B175 -> Patricia Moore | C22: =Analysis!C175 -> 9799.73 | E22: =INDEX(Analysis!$B$93:$B$102,MATCH(4,Analysis!$H$93:$H$102,0)) -> Monitor | F22: =INDEX(Analysis!$E$93:$E$102,MATCH(4,Analysis!$H$93:$H$102,0)) -> 88
B23: =Analysis!B176 -> Paul Baker | C23: =Analysis!C176 -> 8309.74 | E23: =INDEX(Analysis!$B$93:$B$102,MATCH(5,Analysis!$H$93:$H$102,0)) -> Blender | F23: =INDEX(Analysis!$E$93:$E$102,MATCH(5,Analysis!$H$93:$H$102,0)) -> 87
B25: Regional sales (ranked)
B26: Region | C26: Revenue | D26: Share
B27: =INDEX(Analysis!$A$67:$A$71,MATCH(1,Analysis!$H$67:$H$71,0)) -> East | C27: =INDEX(Analysis!$C$67:$C$71,MATCH(1,Analysis!$H$67:$H$71,0)) -> 59288.39 | D27: =INDEX(Analysis!$G$67:$G$71,MATCH(1,Analysis!$H$67:$H$71,0)) -> 0.25868385
B28: =INDEX(Analysis!$A$67:$A$71,MATCH(2,Analysis!$H$67:$H$71,0)) -> North | C28: =INDEX(Analysis!$C$67:$C$71,MATCH(2,Analysis!$H$67:$H$71,0)) -> 50808.31 | D28: =INDEX(Analysis!$G$67:$G$71,MATCH(2,Analysis!$H$67:$H$71,0)) -> 0.22168403
B29: =INDEX(Analysis!$A$67:$A$71,MATCH(3,Analysis!$H$67:$H$71,0)) -> West | C29: =INDEX(Analysis!$C$67:$C$71,MATCH(3,Analysis!$H$67:$H$71,0)) -> 41408.68 | D29: =INDEX(Analysis!$G$67:$G$71,MATCH(3,Analysis!$H$67:$H$71,0)) -> 0.18067208
B30: =INDEX(Analysis!$A$67:$A$71,MATCH(4,Analysis!$H$67:$H$71,0)) -> Central | C30: =INDEX(Analysis!$C$67:$C$71,MATCH(4,Analysis!$H$67:$H$71,0)) -> 41288.34 | D30: =INDEX(Analysis!$G$67:$G$71,MATCH(4,Analysis!$H$67:$H$71,0)) -> 0.18014702
B31: =INDEX(Analysis!$A$67:$A$71,MATCH(5,Analysis!$H$67:$H$71,0)) -> South | C31: =INDEX(Analysis!$C$67:$C$71,MATCH(5,Analysis!$H$67:$H$71,0)) -> 36398.75 | D31: =INDEX(Analysis!$G$67:$G$71,MATCH(5,Analysis!$H$67:$H$71,0)) -> 0.15881303
B33: 3. The story in the data
B34: Who buys | C34: ="Revenue is concentrated: the "&Analysis!$B$165&" high-value customers (top "&TEXT(1-Analysis!$B$109,"0%")&" by spend) generate "&TEXT(Analysis!$B$166,"0.0%")&" of all revenue. "&Analysis!$B$26&" leads with "&Analysis!$C$26&"; "&Analysis!$B$164&" of "&Analysis!$B$25&" customers bought more than once, and "&Analysis!$B$167&" is the most frequently repeating name ("&Analysis!$C$167&" purchases)." -> Revenue is concentrated: the 10 high-value customers (top 20% by spend) generate 41.0% of all revenue. Mark Carter leads with ₹15,659.65 total spend; 47 of 50 customers bought more than once, and Mark Carter is the most frequently repeating name (12 purchases).
B35: What sells | C35: =Analysis!$B$104&" is the most sold product ("&TEXT(Analysis!$C$104,"0")&"), while "&Analysis!$B$105&" earns the most money ("&TEXT(Analysis!$C$105,"[>=10000000]\₹##\,##\,##\,##0;[>=100000]\₹##\,##\,##0;\₹#,##0")&"). "&INDEX(Analysis!$A$76:$A$78,MATCH(MAX(Analysis!$E$76:$E$78),Analysis!$E$76:$E$78,0))&" is the biggest category with "&TEXT(MAX(Analysis!$E$76:$E$78),"0.0%")&" of revenue. The product that sells the most units is not always the one that earns the most." -> Bookshelf is the most sold product (102), while Laptop earns the most money (₹67,499). Electronics is the biggest category with 74.9% of revenue. The product that sells the most units is not always the one that earns the most.
B36: Where | C36: =Analysis!$B$29&" is the strongest region with "&TEXT(INDEX(Analysis!$G$67:$G$71,MATCH(1,Analysis!$H$67:$H$71,0)),"0.0%")&" of revenue, and "&Analysis!$B$30&" the weakest with "&TEXT(INDEX(Analysis!$G$67:$G$71,MATCH(5,Analysis!$H$67:$H$71,0)),"0.0%")&"." -> East is the strongest region with 25.9% of revenue, and South the weakest with 15.9%.
B37: When | C37: ="Revenue peaked in "&Analysis!$B$31&" ("&Analysis!$C$31&"). The monthly line on the Visualizations and Dashboard sheets shows how demand moves from month to month; the final month is partial because data stops on "&TEXT(Analysis!$B$39,"dd mmm yyyy")&"." -> Revenue peaked in Jan 2025 (₹25,799.15 revenue). The monthly line on the Visualizations and Dashboard sheets shows how demand moves from month to month; the final month is partial because data stops on 11 Apr 2025.
B38: How they pay | C38: =INDEX(Analysis!$A$81:$A$84,MATCH(MAX(Analysis!$B$81:$B$84),Analysis!$B$81:$B$84,0))&" is the largest payment method, carrying "&TEXT(MAX(Analysis!$E$81:$E$84),"0.0%")&" of revenue." -> Credit Card is the largest payment method, carrying 26.8% of revenue.
B39: Cross-selling | C39: ="Of the customers who bought "&Analysis!$B$185&" ("&Analysis!$G$189&") and those who bought "&Analysis!$B$186&" ("&Analysis!$G$190&"), "&Analysis!$G$191&" bought both – a ready-made audience for bundle offers." -> Of the customers who bought Electronics (44) and those who bought Furniture (37), 34 bought both – a ready-made audience for bundle offers.
B40: What drives order value | C40: ="Regression: each extra unit adds about "&TEXT(Analysis!$B$301,"[>=10000000]\₹##\,##\,##\,##0;[>=100000]\₹##\,##\,##0;\₹#,##0")&" and each ₹1 of unit price about "&TEXT(Analysis!$B$302,"\₹0.00")&" to a transaction; quantity and price together explain "&TEXT(Analysis!$B$288,"0.0%")&" of the variation in order value (R²), and the model is statistically significant (Significance F = "&TEXT(Analysis!$F$295,"0.0E+00")&")." -> Regression: each extra unit adds about ₹314 and each ₹1 of unit price about ₹3.04 to a transaction; quantity and price together explain 86.3% of the variation in order value (R²), and the model is statistically significant (Significance F = 3.0E-107).
B41: What-if | C41: ="Scenario analysis: the worst case ("&TEXT(Analysis!$B$262,"[>=10000000]\₹##\,##\,##\,##0;[>=100000]\₹##\,##\,##0;\₹#,##0")&") to best case ("&TEXT(Analysis!$D$262,"[>=10000000]\₹##\,##\,##\,##0;[>=100000]\₹##\,##\,##0;\₹#,##0")&") brackets baseline revenue of "&TEXT(Analysis!$B$21,"[>=10000000]\₹##\,##\,##\,##0;[>=100000]\₹##\,##\,##0;\₹#,##0")&". Goal Seek shows that reaching "&TEXT(Analysis!$B$267,"[>=10000000]\₹##\,##\,##\,##0;[>=100000]\₹##\,##\,##0;\₹#,##0")&" needs "&TEXT(Analysis!$B$269,"0.0%")&" more units at today's prices." -> Scenario analysis: the worst case (₹1,95,960) to best case (₹2,76,750) brackets baseline revenue of ₹2,29,192. Goal Seek shows that reaching ₹2,50,000 needs 9.1% more units at today's prices.
B43: 4. Recommendations
B44: ="1. Protect the "&Analysis!$B$165&" high-value customers with a loyalty or account-management programme – they carry "&TEXT(Analysis!$B$166,"0%")&" of revenue." -> 1. Protect the 10 high-value customers with a loyalty or account-management programme – they carry 41% of revenue.
B45: ="2. Keep "&Analysis!$B$104&" and "&Analysis!$B$105&" fully stocked and promoted; they lead on volume and on revenue." -> 2. Keep Bookshelf and Laptop fully stocked and promoted; they lead on volume and on revenue.
B46: ="3. Lift "&Analysis!$B$30&" with targeted campaigns, using "&Analysis!$B$29&" as the playbook." -> 3. Lift South with targeted campaigns, using East as the playbook.
...
